Workbook

Sheet Допущения
A1: MakeMeLook Widget — допущения
A2: Жёлтые ячейки — редактируйте. Всё остальное считается формулами.
A4: Параметр | B4: Значение | C4: Ед. | D4: Обоснование / источник
A5: ЦЕНЫ И КУРС
A6: Курс доллара | B6: 86 | C6: ₽/$ | D6: Задан 09.09.2026
A7: Цена примерки | B7: 10 | C7: ₽ | D7: Сценарий
A8: Setup fee (разовый при подключении) | B8: 30000 | C8: ₽ | D8: Сценарий
A9: ПРИВЛЕЧЕНИЕ КЛИЕНТОВ
A10: Бюджет маркетинга старт | B10: 0 | C10: ₽/мес | D10: Сейчас 0: холодная рассылка своими руками, платного трафика нет
A11: Бюджет маркетинга целевой | B11: 0 | C11: ₽/мес | D11: Поднимите, если решите закупать трафик
A12: Месяцев до целевого бюджета | B12: 12 | C12: мес | D12: ДОПУЩЕНИЕ: линейный рост
A13: Цена контакта (маркетинг) | B13: 3000 | C13: ₽ | D13: ДОПУЩЕНИЕ: нишевый B2B fashion
A14: Контактов от исходящих на 1 сейлза | B14: 30 | C14: шт/мес | D14: ДОПУЩЕНИЕ: холодная рассылка, плейбук на 102 магазина
A15: Конверсия контакт → интеграция | B15: 0.04 | C15: % | D15: ДОПУЩЕНИЕ: холодный B2B. НЕ ПРОВЕРЕНО на практике
A16: Органика (входящие) в месяц | B16: 1 | C16: шт/мес | D16: ДОПУЩЕНИЕ: сарафан + сайт
A17: Churn активных клиентов | B17: 0.04 | C17: %/мес | D17: ДОПУЩЕНИЕ: ~40% в год
A18: ОБЪЁМ ПРИМЕРОК
A19: Примерок на клиента в 1-й месяц | B19: 1500 | C19: шт | D19: Ramp-up: магазин раскачивается не сразу
A20: Примерок на зрелого клиента | B20: 4000 | C20: шт/мес | D20: ДАННЫЕ ВЛАДЕЛЬЦА: в среднем 3–5к на магазин
A21: Месяцев до зрелости клиента | B21: 3 | C21: мес | D21: ДОПУЩЕНИЕ
A22: СЕБЕСТОИМОСТЬ AI (замеры 09.09.2026)
A23: Input-токены | B23: 4 | C23: $/1M | D23: Прайс CometAPI gpt-image-2.5 (−20% от OpenAI)
A24: Output-токены | B24: 24 | C24: $/1M | D24: Прайс CometAPI
A25: Input-токенов: 1 вещь | B25: 3928 | C25: ток. | D25: ЗАМЕР на реальном запросе
A26: Input-токенов за след. вещь | B26: 1869 | C26: ток. | D26: ЗАМЕР: (9535−3928)/3
A27: Output-токенов на результат | B27: 1316 | C27: ток. | D27: 1120 картинка + 196 текст
A28: Средневзвеш. вещей в образе | B28: 1.24 | C28: шт | D28: ФАКТ из БД: 79,6/15,4/4,2/0,7% по 1-4 вещам
A29: Доля лишних оплаченных попыток | B29: 0.195 | C29: % | D29: ФАКТ: (242 ошибки + 130 ретраев)/1903
A30: Доля стоимости неуспешной попытки | B30: 0.36 | C30: % | D30: ДОПУЩЕНИЕ: биллится только input
A31: Валидация фото: цена вызова | B31: 0.0134 | C31: ₽ | D31: Расчёт: 1700 in + 60 out по $0,08/$0,32 за 1M
A32: Примерок на 1 загруженное фото | B32: 3.08 | C32: шт | D32: ФАКТ: 2145/697
A33: Хранение на примерку | B33: 0.0089 | C33: ₽ | D33: 0,76 МБ × ₽4,09/ГБ × 3 мес × 3 (бэкапы)
A34: ОБСЛУЖИВАНИЕ КЛИЕНТА
A35: Онбординг нового клиента | B35: 0 | C35: ₽ | D35: 0 = делаете сами, деньгами не платите. Впишите, если наймёте
A36: Поддержка активного клиента | B36: 0 | C36: ₽/мес | D36: 0 = делаете сами. Впишите, если наймёте
A37: Комиссия эквайринга | B37: 0.02 | C37: % | D37: ДОПУЩЕНИЕ: 2%; по счёту = 0
A38: OPEX
A39: Сервисы IT / инфра | B39: 5000 | C39: ₽/мес | D39: Реальная доля Hetzner (~15% от €40) + домены
A40: Рост IT-расходов | B40: 0.05 | C40: %/мес | D40: ДОПУЩЕНИЕ
A41: Бухгалтерия / юрист | B41: 15000 | C41: ₽/мес | D41: Обслуживание ООО. Разовый юрист по 152-ФЗ — отдельно
...

Sheet Команда
A1: План найма
A2: Оклад gross. «Месяц найма» — с какого месяца человек в ФОТ. Пусто = не нанят.
A4: Роль | B4: Оклад gross, ₽ | C4: Месяц найма | D4: Сейлз (1/0) | E4: Комментарий
A5: Фаундер (вы) | B5: 0 | C5: 1 | D5: 1 | E5: Зарплату не берёте. Считаетесь как 1 сейлз для воронки
A6: Найм #1 (напр. сейлз) | B6: 90000 | D6: 1 | E6: Пусто в «Месяц найма» = не нанят. Впишите месяц, когда потянете
A7: Найм #2 (напр. поддержка) | B7: 70000 | D7: 0 | E7: Пусто = не нанят
A8: Найм #3 | B8: 0 | D8: 0 | E8: Резерв
A9: Найм #4 | B9: 0 | D9: 0 | E9: Резерв

Sheet Модель
A1: Финансовая модель по месяцам — 12 месяцев
A3: Месяц | B3: Сен'26 | C3: Окт'26 | D3: Ноя'26 | E3: Дек'26 | F3: Янв'27 | G3: Фев'27 | H3: Мар'27 | I3: Апр'27 | J3: Май'27 | K3: Июн'27 | L3: Июл'27 | M3: Авг'27 | N3: ИТОГО / ИТОГ
A4: № месяца | B4: 1 | C4: 2 | D4: 3 | E4: 4 | F4: 5 | G4: 6 | H4: 7 | I4: 8 | J4: 9 | K4: 10 | L4: 11 | M4: 12
A5: Сезонность | B5: 1 | C5: 1.05 | D5: 1.05 | E5: 0.95 | F5: 0.6 | G5: 0.85 | H5: 1 | I5: 1 | J5: 1.05 | K5: 0.95 | L5: 0.8 | M5: 0.85
A7: ПРИВЛЕЧЕНИЕ КЛИЕНТОВ
A8: Бюджет маркетинга | B8: =MIN(Допущения!$B$10+(Допущения!$B$11-Допущения!$B$10)/Допущения!$B$12*(B4-1),Допущения!$B$11) | C8: =MIN(Допущения!$B$10+(Допущения!$B$11-Допущения!$B$10)/Допущения!$B$12*(C4-1),Допущения!$B$11) | D8: =MIN(Допущения!$B$10+(Допущения!$B$11-Допущения!$B$10)/Допущения!$B$12*(D4-1),Допущения!$B$11) | E8: =MIN(Допущения!$B$10+(Допущения!$B$11-Допущения!$B$10)/Допущения!$B$12*(E4-1),Допущения!$B$11) | F8: =MIN(Допущения!$B$10+(Допущения!$B$11-Допущения!$B$10)/Допущения!$B$12*(F4-1),Допущения!$B$11) | G8: =MIN(Допущения!$B$10+(Допущения!$B$11-Допущения!$B$10)/Допущения!$B$12*(G4-1),Допущения!$B$11) | H8: =MIN(Допущения!$B$10+(Допущения!$B$11-Допущения!$B$10)/Допущения!$B$12*(H4-1),Допущения!$B$11) | I8: =MIN(Допущения!$B$10+(Допущения!$B$11-Допущения!$B$10)/Допущения!$B$12*(I4-1),Допущения!$B$11) | ... M8: =MIN(Допущения!$B$10+(Допущения!$B$11-Допущения!$B$10)/Допущения!$B$12*(M4-1),Допущения!$B$11) | N8: =SUM(B8:M8)
A9: Контактов от маркетинга | B9: =ROUND(B8/Допущения!$B$13,0) | C9: =ROUND(C8/Допущения!$B$13,0) | D9: =ROUND(D8/Допущения!$B$13,0) | E9: =ROUND(E8/Допущения!$B$13,0) | F9: =ROUND(F8/Допущения!$B$13,0) | G9: =ROUND(G8/Допущения!$B$13,0) | H9: =ROUND(H8/Допущения!$B$13,0) | I9: =ROUND(I8/Допущения!$B$13,0) | ... M9: =ROUND(M8/Допущения!$B$13,0) | N9: =SUM(B9:M9)
A10: Контактов от исходящих | B10: =ROUND(SUMPRODUCT((ISNUMBER('Команда'!$C$5:$C$9))*('Команда'!$C$5:$C$9<=B4)*'Команда'!$D$5:$D$9)*Допущения!$B$14,0) | C10: =ROUND(SUMPRODUCT((ISNUMBER('Команда'!$C$5:$C$9))*('Команда'!$C$5:$C$9<=C4)*'Команда'!$D$5:$D$9)*Допущения!$B$14,0) | D10: =ROUND(SUMPRODUCT((ISNUMBER('Команда'!$C$5:$C$9))*('Команда'!$C$5:$C$9<=D4)*'Команда'!$D$5:$D$9)*Допущения!$B$14,0) | E10: =ROUND(SUMPRODUCT((ISNUMBER('Команда'!$C$5:$C$9))*('Команда'!$C$5:$C$9<=E4)*'Команда'!$D$5:$D$9)*Допущения!$B$14,0) | F10: =ROUND(SUMPRODUCT((ISNUMBER('Команда'!$C$5:$C$9))*('Команда'!$C$5:$C$9<=F4)*'Команда'!$D$5:$D$9)*Допущения!$B$14,0) | G10: =ROUND(SUMPRODUCT((ISNUMBER('Команда'!$C$5:$C$9))*('Команда'!$C$5:$C$9<=G4)*'Команда'!$D$5:$D$9)*Допущения!$B$14,0) | H10: =ROUND(SUMPRODUCT((ISNUMBER('Команда'!$C$5:$C$9))*('Команда'!$C$5:$C$9<=H4)*'Команда'!$D$5:$D$9)*Допущения!$B$14,0) | I10: =ROUND(SUMPRODUCT((ISNUMBER('Команда'!$C$5:$C$9))*('Команда'!$C$5:$C$9<=I4)*'Команда'!$D$5:$D$9)*Допущения!$B$14,0) | ... M10: =ROUND(SUMPRODUCT((ISNUMBER('Команда'!$C$5:$C$9))*('Команда'!$C$5:$C$9<=M4)*'Команда'!$D$5:$D$9)*Допущения!$B$14,0) | N10: =SUM(B10:M10)
A11: Всего контактов | B11: =B9+B10 | C11: =C9+C10 | D11: =D9+D10 | E11: =E9+E10 | F11: =F9+F10 | G11: =G9+G10 | H11: =H9+H10 | I11: =I9+I10 | ... M11: =M9+M10 | N11: =SUM(B11:M11)
A12: Новых интеграций | B12: =ROUND(B11*Допущения!$B$15,0)+Допущения!$B$16 | C12: =ROUND(C11*Допущения!$B$15,0)+Допущения!$B$16 | D12: =ROUND(D11*Допущения!$B$15,0)+Допущения!$B$16 | E12: =ROUND(E11*Допущения!$B$15,0)+Допущения!$B$16 | F12: =ROUND(F11*Допущения!$B$15,0)+Допущения!$B$16 | G12: =ROUND(G11*Допущения!$B$15,0)+Допущения!$B$16 | H12: =ROUND(H11*Допущения!$B$15,0)+Допущения!$B$16 | I12: =ROUND(I11*Допущения!$B$15,0)+Допущения!$B$16 | ... M12: =ROUND(M11*Допущения!$B$15,0)+Допущения!$B$16 | N12: =SUM(B12:M12)
A13: Отток | B13: =0 | C13: =-ROUND(B14*Допущения!$B$17,0) | D13: =-ROUND(C14*Допущения!$B$17,0) | E13: =-ROUND(D14*Допущения!$B$17,0) | F13: =-ROUND(E14*Допущения!$B$17,0) | G13: =-ROUND(F14*Допущения!$B$17,0) | H13: =-ROUND(G14*Допущения!$B$17,0) | I13: =-ROUND(H14*Допущения!$B$17,0) | J13: =-ROUND(I14*Допущения!$B$17,0) | ... M13: =-ROUND(L14*Допущения!$B$17,0) | N13: =SUM(B13:M13)
A14: Активных клиентов | B14: =B12 | C14: =B14+C12+C13 | D14: =C14+D12+D13 | E14: =D14+E12+E13 | F14: =E14+F12+F13 | G14: =F14+G12+G13 | H14: =G14+H12+H13 | I14: =H14+I12+I13 | J14: =I14+J12+J13 | ... M14: =L14+M12+M13 | N14: =M14
A16: ОБЪЁМ ПРИМЕРОК
A17: Примерок на клиента/мес | B17: =ROUND(MIN(Допущения!$B$20,Допущения!$B$19+(Допущения!$B$20-Допущения!$B$19)/Допущения!$B$21*(B4-1))*B5,0) | C17: =ROUND(MIN(Допущения!$B$20,Допущения!$B$19+(Допущения!$B$20-Допущения!$B$19)/Допущения!$B$21*(C4-1))*C5,0) | D17: =ROUND(MIN(Допущения!$B$20,Допущения!$B$19+(Допущения!$B$20-Допущения!$B$19)/Допущения!$B$21*(D4-1))*D5,0) | E17: =ROUND(MIN(Допущения!$B$20,Допущения!$B$19+(Допущения!$B$20-Допущения!$B$19)/Допущения!$B$21*(E4-1))*E5,0) | F17: =ROUND(MIN(Допущения!$B$20,Допущения!$B$19+(Допущения!$B$20-Допущения!$B$19)/Допущения!$B$21*(F4-1))*F5,0) | G17: =ROUND(MIN(Допущения!$B$20,Допущения!$B$19+(Допущения!$B$20-Допущения!$B$19)/Допущения!$B$21*(G4-1))*G5,0) | H17: =ROUND(MIN(Допущения!$B$20,Допущения!$B$19+(Допущения!$B$20-Допущения!$B$19)/Допущения!$B$21*(H4-1))*H5,0) | I17: =ROUND(MIN(Допущения!$B$20,Допущения!$B$19+(Допущения!$B$20-Допущения!$B$19)/Допущения!$B$21*(I4-1))*I5,0) | ... M17: =ROUND(MIN(Допущения!$B$20,Допущения!$B$19+(Допущения!$B$20-Допущения!$B$19)/Допущения!$B$21*(M4-1))*M5,0) | N17: =IFERROR(AVERAGE(B17:M17),0)
A18: Всего примерок | B18: =B14*B17 | C18: =C14*C17 | D18: =D14*D17 | E18: =E14*E17 | F18: =F14*F17 | G18: =G14*G17 | H18: =H14*H17 | I18: =I14*I17 | ... M18: =M14*M17 | N18: =SUM(B18:M18)
A20: ВЫРУЧКА
A21: Setup fee (новые клиенты) | B21: =B12*Допущения!$B$8 | C21: =C12*Допущения!$B$8 | D21: =D12*Допущения!$B$8 | E21: =E12*Допущения!$B$8 | F21: =F12*Допущения!$B$8 | G21: =G12*Допущения!$B$8 | H21: =H12*Допущения!$B$8 | I21: =I12*Допущения!$B$8 | ... M21: =M12*Допущения!$B$8 | N21: =SUM(B21:M21)
A22: Выручка с примерок | B22: =B18*Допущения!$B$7 | C22: =C18*Допущения!$B$7 | D22: =D18*Допущения!$B$7 | E22: =E18*Допущения!$B$7 | F22: =F18*Допущения!$B$7 | G22: =G18*Допущения!$B$7 | H22: =H18*Допущения!$B$7 | I22: =I18*Допущения!$B$7 | ... M22: =M18*Допущения!$B$7 | N22: =SUM(B22:M22)
A23: ВЫРУЧКА ВСЕГО | B23: =B21+B22 | C23: =C21+C22 | D23: =D21+D22 | E23: =E21+E22 | F23: =F21+F22 | G23: =G21+G22 | H23: =H21+H22 | I23: =I21+I22 | ... M23: =M21+M22 | N23: =SUM(B23:M23)
A25: СЕБЕСТОИМОСТЬ
A26: AI-генерация | B26: =-B18*((Допущения!$B$25+(Допущения!$B$28-1)*Допущения!$B$26)*Допущения!$B$23/1000000+Допущения!$B$27*Допущения!$B$24/1000000)*Допущения!$B$6 | C26: =-C18*((Допущения!$B$25+(Допущения!$B$28-1)*Допущения!$B$26)*Допущения!$B$23/1000000+Допущения!$B$27*Допущения!$B$24/1000000)*Допущения!$B$6 | D26: =-D18*((Допущения!$B$25+(Допущения!$B$28-1)*Допущения!$B$26)*Допущения!$B$23/1000000+Допущения!$B$27*Допущения!$B$24/1000000)*Допущения!$B$6 | E26: =-E18*((Допущения!$B$25+(Допущения!$B$28-1)*Допущения!$B$26)*Допущения!$B$23/1000000+Допущения!$B$27*Допущения!$B$24/1000000)*Допущения!$B$6 | F26: =-F18*((Допущения!$B$25+(Допущения!$B$28-1)*Допущения!$B$26)*Допущения!$B$23/1000000+Допущения!$B$27*Допущения!$B$24/1000000)*Допущения!$B$6 | G26: =-G18*((Допущения!$B$25+(Допущения!$B$28-1)*Допущения!$B$26)*Допущения!$B$23/1000000+Допущения!$B$27*Допущения!$B$24/1000000)*Допущения!$B$6 | H26: =-H18*((Допущения!$B$25+(Допущения!$B$28-1)*Допущения!$B$26)*Допущения!$B$23/1000000+Допущения!$B$27*Допущения!$B$24/1000000)*Допущения!$B$6 | I26: =-I18*((Допущения!$B$25+(Допущения!$B$28-1)*Допущения!$B$26)*Допущения!$B$23/1000000+Допущения!$B$27*Допущения!$B$24/1000000)*Допущения!$B$6 | ... M26: =-M18*((Допущения!$B$25+(Допущения!$B$28-1)*Допущения!$B$26)*Допущения!$B$23/1000000+Допущения!$B$27*Допущения!$B$24/1000000)*Допущения!$B$6 | N26: =SUM(B26:M26)
A27: Отказы и ретраи | B27: =B26*Допущения!$B$29*Допущения!$B$30 | C27: =C26*Допущения!$B$29*Допущения!$B$30 | D27: =D26*Допущения!$B$29*Допущения!$B$30 | E27: =E26*Допущения!$B$29*Допущения!$B$30 | F27: =F26*Допущения!$B$29*Допущения!$B$30 | G27: =G26*Допущения!$B$29*Допущения!$B$30 | H27: =H26*Допущения!$B$29*Допущения!$B$30 | I27: =I26*Допущения!$B$29*Допущения!$B$30 | ... M27: =M26*Допущения!$B$29*Допущения!$B$30 | N27: =SUM(B27:M27)
A28: Валидация фото | B28: =-B18*Допущения!$B$31*1.25/Допущения!$B$32 | C28: =-C18*Допущения!$B$31*1.25/Допущения!$B$32 | D28: =-D18*Допущения!$B$31*1.25/Допущения!$B$32 | E28: =-E18*Допущения!$B$31*1.25/Допущения!$B$32 | F28: =-F18*Допущения!$B$31*1.25/Допущения!$B$32 | G28: =-G18*Допущения!$B$31*1.25/Допущения!$B$32 | H28: =-H18*Допущения!$B$31*1.25/Допущения!$B$32 | I28: =-I18*Допущения!$B$31*1.25/Допущения!$B$32 | ... M28: =-M18*Допущения!$B$31*1.25/Допущения!$B$32 | N28: =SUM(B28:M28)
A29: Хранение | B29: =-B18*Допущения!$B$33 | C29: =-C18*Допущения!$B$33 | D29: =-D18*Допущения!$B$33 | E29: =-E18*Допущения!$B$33 | F29: =-F18*Допущения!$B$33 | G29: =-G18*Допущения!$B$33 | H29: =-H18*Допущения!$B$33 | I29: =-I18*Допущения!$B$33 | ... M29: =-M18*Допущения!$B$33 | N29: =SUM(B29:M29)
A30: Эквайринг | B30: =-B23*Допущения!$B$37 | C30: =-C23*Допущения!$B$37 | D30: =-D23*Допущения!$B$37 | E30: =-E23*Допущения!$B$37 | F30: =-F23*Допущения!$B$37 | G30: =-G23*Допущения!$B$37 | H30: =-H23*Допущения!$B$37 | I30: =-I23*Допущения!$B$37 | ... M30: =-M23*Допущения!$B$37 | N30: =SUM(B30:M30)
A31: Онбординг новых клиентов | B31: =-B12*Допущения!$B$35 | C31: =-C12*Допущения!$B$35 | D31: =-D12*Допущения!$B$35 | E31: =-E12*Допущения!$B$35 | F31: =-F12*Допущения!$B$35 | G31: =-G12*Допущения!$B$35 | H31: =-H12*Допущения!$B$35 | I31: =-I12*Допущения!$B$35 | ... M31: =-M12*Допущения!$B$35 | N31: =SUM(B31:M31)
A32: Поддержка активных | B32: =-B14*Допущения!$B$36 | C32: =-C14*Допущения!$B$36 | D32: =-D14*Допущения!$B$36 | E32: =-E14*Допущения!$B$36 | F32: =-F14*Допущения!$B$36 | G32: =-G14*Допущения!$B$36 | H32: =-H14*Допущения!$B$36 | I32: =-I14*Допущения!$B$36 | ... M32: =-M14*Допущения!$B$36 | N32: =SUM(B32:M32)
A33: ИТОГО СЕБЕСТОИМОСТЬ | B33: =SUM(B26:B32) | C33: =SUM(C26:C32) | D33: =SUM(D26:D32) | E33: =SUM(E26:E32) | F33: =SUM(F26:F32) | G33: =SUM(G26:G32) | H33: =SUM(H26:H32) | I33: =SUM(I26:I32) | ... M33: =SUM(M26:M32) | N33: =SUM(B33:M33)
A34: ВАЛОВАЯ ПРИБЫЛЬ | B34: =B23+B33 | C34: =C23+C33 | D34: =D23+D33 | E34: =E23+E33 | F34: =F23+F33 | G34: =G23+G33 | H34: =H23+H33 | I34: =I23+I33 | ... M34: =M23+M33 | N34: =SUM(B34:M34)
A35: Валовая маржа | B35: =IFERROR(B34/B23,0) | C35: =IFERROR(C34/C23,0) | D35: =IFERROR(D34/D23,0) | E35: =IFERROR(E34/E23,0) | F35: =IFERROR(F34/F23,0) | G35: =IFERROR(G34/G23,0) | H35: =IFERROR(H34/H23,0) | I35: =IFERROR(I34/I23,0) | ... M35: =IFERROR(M34/M23,0) | N35: =IFERROR(AVERAGE(B35:M35),0)
A37: КОМАНДА
A38: Сотрудников | B38: =SUMPRODUCT((ISNUMBER('Команда'!$C$5:$C$9))*('Команда'!$C$5:$C$9<=B4)) | C38: =SUMPRODUCT((ISNUMBER('Команда'!$C$5:$C$9))*('Команда'!$C$5:$C$9<=C4)) | D38: =SUMPRODUCT((ISNUMBER('Команда'!$C$5:$C$9))*('Команда'!$C$5:$C$9<=D4)) | E38: =SUMPRODUCT((ISNUMBER('Команда'!$C$5:$C$9))*('Команда'!$C$5:$C$9<=E4)) | F38: =SUMPRODUCT((ISNUMBER('Команда'!$C$5:$C$9))*('Команда'!$C$5:$C$9<=F4)) | G38: =SUMPRODUCT((ISNUMBER('Команда'!$C$5:$C$9))*('Команда'!$C$5:$C$9<=G4)) | H38: =SUMPRODUCT((ISNUMBER('Команда'!$C$5:$C$9))*('Команда'!$C$5:$C$9<=H4)) | I38: =SUMPRODUCT((ISNUMBER('Команда'!$C$5:$C$9))*('Команда'!$C$5:$C$9<=I4)) | ... M38: =SUMPRODUCT((ISNUMBER('Команда'!$C$5:$C$9))*('Команда'!$C$5:$C$9<=M4)) | N38: =M38
A39: ФОТ gross | B39: =-SUMPRODUCT((ISNUMBER('Команда'!$C$5:$C$9))*('Команда'!$C$5:$C$9<=B4)*'Команда'!$B$5:$B$9) | C39: =-SUMPRODUCT((ISNUMBER('Команда'!$C$5:$C$9))*('Команда'!$C$5:$C$9<=C4)*'Команда'!$B$5:$B$9) | D39: =-SUMPRODUCT((ISNUMBER('Команда'!$C$5:$C$9))*('Команда'!$C$5:$C$9<=D4)*'Команда'!$B$5:$B$9) | E39: =-SUMPRODUCT((ISNUMBER('Команда'!$C$5:$C$9))*('Команда'!$C$5:$C$9<=E4)*'Команда'!$B$5:$B$9) | F39: =-SUMPRODUCT((ISNUMBER('Команда'!$C$5:$C$9))*('Команда'!$C$5:$C$9<=F4)*'Команда'!$B$5:$B$9) | G39: =-SUMPRODUCT((ISNUMBER('Команда'!$C$5:$C$9))*('Команда'!$C$5:$C$9<=G4)*'Команда'!$B$5:$B$9) | H39: =-SUMPRODUCT((ISNUMBER('Команда'!$C$5:$C$9))*('Команда'!$C$5:$C$9<=H4)*'Команда'!$B$5:$B$9) | I39: =-SUMPRODUCT((ISNUMBER('Команда'!$C$5:$C$9))*('Команда'!$C$5:$C$9<=I4)*'Команда'!$B$5:$B$9) | ... M39: =-SUMPRODUCT((ISNUMBER('Команда'!$C$5:$C$9))*('Команда'!$C$5:$C$9<=M4)*'Команда'!$B$5:$B$9) | N39: =SUM(B39:M39)
A40: Налоги на ФОТ | B40: =B39*Допущения!$B$46 | C40: =C39*Допущения!$B$46 | D40: =D39*Допущения!$B$46 | E40: =E39*Допущения!$B$46 | F40: =F39*Допущения!$B$46 | G40: =G39*Допущения!$B$46 | H40: =H39*Допущения!$B$46 | I40: =I39*Допущения!$B$46 | ... M40: =M39*Допущения!$B$46 | N40: =SUM(B40:M40)
A41: ФОТ с налогами | B41: =B39+B40 | C41: =C39+C40 | D41: =D39+D40 | E41: =E39+E40 | F41: =F39+F40 | G41: =G39+G40 | H41: =H39+H40 | I41: =I39+I40 | ... M41: =M39+M40 | N41: =SUM(B41:M41)
A43: OPEX
A44: Маркетинг | B44: =-B8 | C44: =-C8 | D44: =-D8 | E44: =-E8 | F44: =-F8 | G44: =-G8 | H44: =-H8 | I44: =-I8 | ... M44: =-M8 | N44: =SUM(B44:M44)
A45: Сервисы IT / инфра | B45: =-Допущения!$B$39 | C45: =B45*(1+Допущения!$B$40) | D45: =C45*(1+Допущения!$B$40) | E45: =D45*(1+Допущения!$B$40) | F45: =E45*(1+Допущения!$B$40) | G45: =F45*(1+Допущения!$B$40) | H45: =G45*(1+Допущения!$B$40) | I45: =H45*(1+Допущения!$B$40) | J45: =I45*(1+Допущения!$B$40) | ... M45: =L45*(1+Допущения!$B$40) | N45: =SUM(B45:M45)
A46: Юрист / бухгалтер | B46: =-Допущения!$B$41 | C46: =-Допущения!$B$41 | D46: =-Допущения!$B$41 | E46: =-Допущения!$B$41 | F46: =-Допущения!$B$41 | G46: =-Допущения!$B$41 | H46: =-Допущения!$B$41 | I46: =-Допущения!$B$41 | ... M46: =-Допущения!$B$41 | N46: =SUM(B46:M46)
A47: Прочие (% выручки) | B47: =-B23*Допущения!$B$42 | C47: =-C23*Допущения!$B$42 | D47: =-D23*Допущения!$B$42 | E47: =-E23*Допущения!$B$42 | F47: =-F23*Допущения!$B$42 | G47: =-G23*Допущения!$B$42 | H47: =-H23*Допущения!$B$42 | I47: =-I23*Допущения!$B$42 | ... M47: =-M23*Допущения!$B$42 | N47: =SUM(B47:M47)
...

Sheet Итоги года
A1: Итоги 12 месяцев
A3: Показатель | B3: Значение | C3: Комментарий
A4: Активных клиентов на конец | B4: ='Модель'!M14 | C4: Накопленная база
A5: Новых интеграций за год | B5: =SUM('Модель'!B12:M12)
A6: Примерок за год | B6: =SUM('Модель'!B18:M18)
A7: Выручка за год | B7: =SUM('Модель'!B23:M23) | C7: Setup fee + примерки
A8: в т.ч. setup fee | B8: =SUM('Модель'!B21:M21)
A9: в т.ч. примерки | B9: =SUM('Модель'!B22:M22)
A10: Себестоимость за год | B10: =-SUM('Модель'!B33:M33)
A11: Валовая прибыль | B11: =SUM('Модель'!B34:M34)
A12: Валовая маржа | B12: =IFERROR(B11/B7,0)
A13: ФОТ с налогами | B13: =-SUM('Модель'!B41:M41)
A14: OPEX | B14: =-SUM('Модель'!B49:M49)
A15: EBITDA | B15: =SUM('Модель'!B53:M53) | C15: Ключевая цифра
A16: EBITDA маржа | B16: =IFERROR(B15/B7,0)
A17: Чистая прибыль | B17: =SUM('Модель'!B56:M56)
A18: Остаток ДС на конец | B18: ='Модель'!M59 | C18: Отрицательный = нужен внешний капитал
A19: Месяц выхода в плюс (EBITDA) | B19: =IFERROR(MATCH(TRUE,INDEX('Модель'!B53:M53>0,0),0),"не выходит") | C19: Номер месяца
A20: ТОЧКА БЕЗУБЫТОЧНОСТИ
A21: Расходы в месяц (OPEX+ФОТ, посл. мес) | B21: =-'Модель'!M50 | C21: Что надо покрыть валовой прибылью
A22: Валовая прибыль с 1 примерки | B22: ='Unit-экономика'!B10 | C22: Контрибуция
A23: Примерок/мес для безубыточности | B23: =IFERROR(B21/B22,0) | C23: Сколько примерок должно идти через виджет
A24: Клиентов для безубыточности | B24: =IFERROR(B23/Допущения!$B$20,0) | C24: При текущей загрузке на клиента
A25: Клиентов сейчас (конец года) | B25: ='Модель'!M14 | C25: Сравните с предыдущей строкой

Sheet Unit-экономика
A1: Юнит-экономика: на примерку и на клиента
A3: Показатель | B3: Значение | C3: Комментарий
A4: НА ОДНУ ПРИМЕРКУ
A5: Цена | B5: =Допущения!$B$7
A6: AI-генерация | B6: =-((Допущения!$B$25+(Допущения!$B$28-1)*Допущения!$B$26)*Допущения!$B$23/1000000+Допущения!$B$27*Допущения!$B$24/1000000)*Допущения!$B$6 | C6: Средневзвеш. по числу вещей
A7: Отказы и ретраи | B7: =B5*Допущения!$B$29*Допущения!$B$30
A8: Валидация фото | B8: =-Допущения!$B$31*1.25/Допущения!$B$32
A9: Хранение | B9: =-Допущения!$B$33
A10: Эквайринг | B10: =-Допущения!$B$7*Допущения!$B$37 | C10: 0 при оплате по счёту
A11: Контрибуция с примерки | B11: =SUM(B4:B9) | C11: Ключевая цифра
A12: Контрибуционная маржа | B12: =B10/Допущения!$B$7
A13: НА ОДНОГО КЛИЕНТА
A14: Setup fee | B14: =Допущения!$B$8
A15: Онбординг | B15: =-Допущения!$B$35
A16: Средний срок жизни | B16: =1/Допущения!$B$17 | C16: 1 / месячный churn, мес
A17: Примерок за жизнь | B17: =B15*Допущения!$B$20
A18: Контрибуция с примерок за жизнь | B18: =B16*B10
A19: Поддержка за жизнь | B19: =-B15*Допущения!$B$36
A20: LTV (валовая, с setup) | B20: =B13+B14+B17+B18 | C20: Ключевая цифра
A21: CAC интеграции (маркетинг) | B21: =Допущения!$B$13/Допущения!$B$15 | C21: CAC лида / конверсия
A22: LTV / CAC | B22: =IFERROR(B19/B20,0) | C22: Норма для SaaS ≥ 3×
A23: Окупаемость подключения, мес | B23: =IFERROR(MAX(0,(Допущения!$B$35+Допущения!$B$13/Допущения!$B$15-Допущения!$B$8)/(Допущения!$B$20*B10-Допущения!$B$36)),0) | C23: 0 = окупается сразу на setup fee

Sheet Риски
A1: Риски модели
A3: # | B3: Риск | C3: Уровень | D3: Что делать
A4: 1 | B4: Токены не пишутся в ai_api_logs (NULL во всех 2144 строках) — себестоимость в проде неизмерима | C4: КРИТИЧНЫЙ | D4: Включить запись, час работы
A5: 2 | B5: Retention по 152-ФЗ не реализован; фото лиц хранятся бессрочно | C5: КРИТИЧНЫЙ | D5: Юрист + автоудаление
A6: 3 | B6: В MinIO 6 фото против 697 записей в БД — 99% ссылок битые | C6: КРИТИЧНЫЙ | D6: Аудит хранилища
A7: 4 | B7: Вся статистика с одного клиента (98,9% примерок — MalinaBonita) | C7: КРИТИЧНЫЙ | D7: Перепроверить после 2-3 клиентов
A8: 5 | B8: Конверсия лид→интеграция 15% — чистое допущение, не проверено на практике | C8: ВЫСОКИЙ | D8: Замерить на первых 20 касаниях
A9: 6 | B9: 300 примерок/мес на клиента — ориентир по одному лучшему клиенту | C9: ВЫСОКИЙ | D9: Заложить сценарий 100/мес
A10: 7 | B10: Диск сервера занят на 84% (47 ГБ свободно) | C10: ВЫСОКИЙ | D10: Расширить до продажи пакетов
A11: 8 | B11: Валютная позиция: выручка в ₽, себестоимость в $ | C11: ВЫСОКИЙ | D11: Индексировать прайс к курсу
A12: 9 | B12: Удвоение цены AI обнуляет маржу (ценовой пол ~14,5 ₽) | C12: ВЫСОКИЙ | D12: Право пересмотра цены в оферте
A13: 10 | B13: Setup fee 30к делает сделку вдвое дороже для мелкого клиента | C13: СРЕДНИЙ | D13: Ступенчатый setup 30/20/0
A14: 11 | B14: Пакеты без срока годности = вечное обязательство | C14: СРЕДНИЙ | D14: Срок 12 мес
A15: 12 | B15: Порог НДС на УСН снижается — съест 5-7 п.п. маржи | C15: СРЕДНИЙ | D15: Проверить с бухгалтером
